Workbook

Sheet 使用说明
B2: 网文拆文工作表 · 使用说明
B4: 配套文件：请与《拆文AI提示词模板.md》一起使用——先用其中的提示词让AI输出结构化内容，再把结果整理粘贴进本表对应表格。
B6: 工作表说明
B7: ① 基础信息：记录书名、作者、类型、总量等基本信息，以及本次拆解的目的。
B8: ② 逐章拆解：核心表格，逐章记录事件、伏笔、爽点类型、情绪、结尾钩子。每次把5~10章内容喂给AI，用提示词模板1生成后粘贴到这里。
B9: ③ 结构总览：把全书划分为几个阶段/卷，标注每阶段的核心冲突与关键转折。阶段字数会根据②自动汇总，无需手填。
B10: ④ 人物卡：记录主要角色的身份、目标、弧线变化和与主角的关系。
B11: ⑤ 节奏统计：全部为公式，自动读取②的数据，统计爽点密度、情绪分布、伏笔回收率等，不需要手动填写。
B12: ⑥ 卖点提炼：拆解完成后，基于前面的表格提炼一句话简介、核心卖点、对标作品等，用于投稿或推广文案。
B14: 使用流程建议
B15: 第一步：在①填写书籍基本信息，明确本次拆解目的（学写作 / 改编短剧 / 提炼简介 / 建立素材库）。
B16: 第二步：通读全书或目录，先在③大致划分阶段和转折点（后续可再调整）。
... B27: 【重要提醒】AI拆解只是辅助草稿，人物设定、事件细节请务必人工核对；若用于二次创作或商用改编，情节和人设需重新原创化，避免抄袭风险。

Sheet 基础信息
A2: 基础信息
A4: 书名 | B4: 示例：诡秘之主 | D4: 总章节数 | E4: 示例：1400
A5: 作者 | B5: 示例：爱潜水的乌贼 | D5: 拆解目的 | E5: 学写作技法 / 改编短剧 / 提炼简介 / 建立素材库
A6: 题材/类型 | B6: 示例：西方奇幻 / 都市脑洞 / 甜宠言情 | D6: 拆解范围 | E6: 示例：全书 / 第1~200章 / 卷一
A7: 平台 | B7: 示例：起点中文网 / 晋江文学城 / 番茄小说 | D7: 拆解人
A8: 连载状态 | B8: 连载中 / 已完结 | D8: 拆解日期
A9: 总字数 | B9: 示例：2000000 | D9: 备注
A12: 橙色底纹为待填写单元格，灰色斜体文字为示例格式，填写时直接覆盖即可。

Sheet 逐章拆解
A1: 章节号 | B1: 章节标题 | C1: 字数 | D1: 所属阶段/卷 | E1: 核心事件（一句话） | F1: 新增角色 | G1: 伏笔埋设 | H1: 伏笔回收 | I1: 爽点/反转类型 | J1: 情绪标签 | K1: 结尾钩子 | L1: 备注
A2: 1 | B2: 被退婚的赘婿 | C2: 3200 | D2: 开篇建置 | E2: 主角当众被未婚妻退婚，众人嘲讽，暗中觉醒神秘系统 | F2: 沈明（未婚妻）、系统AI | G2: 系统提示“宿主怒气值已达100%”但未说明用途 | I2: 打脸 | J2: 爽 | K2: 悬念 | L2: 示例行，请替换或删除，勿保留在正式统计范围内

Sheet 结构总览
A1: 序号 | B1: 阶段/卷名 | C1: 起始章节 | D1: 结束章节 | E1: 阶段字数（自动汇总） | F1: 阶段功能 | G1: 核心冲突 | H1: 关键转折事件
A2: 1 | B2: 开篇建置 | C2: 1 | D2: 15 | E2: =SUMIFS(逐章拆解!$C$3:$C$300,逐章拆解!$D$3:$D$300,B2) -> 0 | F2: 开篇建置 | G2: 主角被退婚，社会性死亡，急需翻身手段 | H2: 获得系统金手指，确立“扮猪吃虎”的主线目标
E3: =SUMIFS(逐章拆解!$C$3:$C$300,逐章拆解!$D$3:$D$300,B3) -> 0
E4: =SUMIFS(逐章拆解!$C$3:$C$300,逐章拆解!$D$3:$D$300,B4) -> 0
E5: =SUMIFS(逐章拆解!$C$3:$C$300,逐章拆解!$D$3:$D$300,B5) -> 0
E6: =SUMIFS(逐章拆解!$C$3:$C$300,逐章拆解!$D$3:$D$300,B6) -> 0
E7: =SUMIFS(逐章拆解!$C$3:$C$300,逐章拆解!$D$3:$D$300,B7) -> 0
E8: =SUMIFS(逐章拆解!$C$3:$C$300,逐章拆解!$D$3:$D$300,B8) -> 0
E9: =SUMIFS(逐章拆解!$C$3:$C$300,逐章拆解!$D$3:$D$300,B9) -> 0
E10: =SUMIFS(逐章拆解!$C$3:$C$300,逐章拆解!$D$3:$D$300,B10) -> 0
E11: =SUMIFS(逐章拆解!$C$3:$C$300,逐章拆解!$D$3:$D$300,B11) -> 0
E12: =SUMIFS(逐章拆解!$C$3:$C$300,逐章拆解!$D$3:$D$300,B12) -> 0
E13: =SUMIFS(逐章拆解!$C$3:$C$300,逐章拆解!$D$3:$D$300,B13) -> 0
E14: =SUMIFS(逐章拆解!$C$3:$C$300,逐章拆解!$D$3:$D$300,B14) -> 0
... E30: =SUMIFS(逐章拆解!$C$3:$C$300,逐章拆解!$D$3:$D$300,B30) -> 0

Sheet 人物卡
A1: 角色姓名 | B1: 身份/阵营 | C1: 首次登场章节 | D1: 核心目标/动机 | E1: 弧线起点 | F1: 弧线终点 | G1: 与主角关系 | H1: 重要程度 | I1: 备注
A2: 沈明 | B2: 反派/前未婚妻家族 | C2: 1 | D2: 维护家族颜面，打压主角以巩固自身婚约地位 | E2: 高高在上、刻薄嘲讽主角的大小姐 | F2: 众叛亲离、向主角求饶的落魄之人 | G2: 情敌/仇人 | H2: 核心配角 | I2: 第一卷主要反派

Sheet 节奏统计
A1: 节奏统计仪表盘（自动计算，数据来源：逐章拆解表 第3~300行）
A3: 基础数据
A4: 总章节数 | B4: =COUNT(逐章拆解!$A$3:$A$300) -> 0
A5: 总字数 | B5: =SUM(逐章拆解!$C$3:$C$300) -> 0
A6: 平均单章字数 | B6: =IFERROR(ROUND(B5/B4,0),0) -> 0
A8: 爽点/反转类型分布
A9: 类型 | B9: 数量 | C9: 占总章节比例
A10: 打脸 | B10: =COUNTIF(逐章拆解!$I$3:$I$300,A10) -> 0 | C10: =IFERROR(B10/$B$4,0) -> 0
A11: 逆袭 | B11: =COUNTIF(逐章拆解!$I$3:$I$300,A11) -> 0 | C11: =IFERROR(B11/$B$4,0) -> 0
A12: 身份揭露 | B12: =COUNTIF(逐章拆解!$I$3:$I$300,A12) -> 0 | C12: =IFERROR(B12/$B$4,0) -> 0
A13: 危机反转 | B13: =COUNTIF(逐章拆解!$I$3:$I$300,A13) -> 0 | C13: =IFERROR(B13/$B$4,0) -> 0
A14: 情感高光 | B14: =COUNTIF(逐章拆解!$I$3:$I$300,A14) -> 0 | C14: =IFERROR(B14/$B$4,0) -> 0
A15: 能力突破 | B15: =COUNTIF(逐章拆解!$I$3:$I$300,A15) -> 0 | C15: =IFERROR(B15/$B$4,0) -> 0
A16: 阴谋算计 | B16: =COUNTIF(逐章拆解!$I$3:$I$300,A16) -> 0 | C16: =IFERROR(B16/$B$4,0) -> 0
A17: 悬念揭晓 | B17: =COUNTIF(逐章拆解!$I$3:$I$300,A17) -> 0 | C17: =IFERROR(B17/$B$4,0) -> 0
A18: 无 | B18: =COUNTIF(逐章拆解!$I$3:$I$300,A18) -> 0 | C18: =IFERROR(B18/$B$4,0) -> 0
A19: 爽点总密度（每几章一个爽点，数值越小越密集） | B19: =IFERROR($B$4/SUM(B10:B17),0) -> 0
A21: 情绪标签分布
A22: 情绪 | B22: 数量 | C22: 占总章节比例
A23: 甜 | B23: =COUNTIF(逐章拆解!$J$3:$J$300,A23) -> 0 | C23: =IFERROR(B23/$B$4,0) -> 0
A24: 虐 | B24: =COUNTIF(逐章拆解!$J$3:$J$300,A24) -> 0 | C24: =IFERROR(B24/$B$4,0) -> 0
A25: 爽 | B25: =COUNTIF(逐章拆解!$J$3:$J$300,A25) -> 0 | C25: =IFERROR(B25/$B$4,0) -> 0
A26: 虐后甜 | B26: =COUNTIF(逐章拆解!$J$3:$J$300,A26) -> 0 | C26: =IFERROR(B26/$B$4,0) -> 0
A27: 紧张 | B27: =COUNTIF(逐章拆解!$J$3:$J$300,A27) -> 0 | C27: =IFERROR(B27/$B$4,0) -> 0
A28: 治愈 | B28: =COUNTIF(逐章拆解!$J$3:$J$300,A28) -> 0 | C28: =IFERROR(B28/$B$4,0) -> 0
A29: 搞笑 | B29: =COUNTIF(逐章拆解!$J$3:$J$300,A29) -> 0 | C29: =IFERROR(B29/$B$4,0) -> 0
A30: 热血 | B30: =COUNTIF(逐章拆解!$J$3:$J$300,A30) -> 0 | C30: =IFERROR(B30/$B$4,0) -> 0
A31: 平淡 | B31: =COUNTIF(逐章拆解!$J$3:$J$300,A31) -> 0 | C31: =IFERROR(B31/$B$4,0) -> 0
A33: 结尾钩子类型分布
A34: 钩子类型 | B34: 数量 | C34: 占总章节比例
A35: 悬念 | B35: =COUNTIF(逐章拆解!$K$3:$K$300,A35) -> 0 | C35: =IFERROR(B35/$B$4,0) -> 0
A36: 危机 | B36: =COUNTIF(逐章拆解!$K$3:$K$300,A36) -> 0 | C36: =IFERROR(B36/$B$4,0) -> 0
A37: 反转 | B37: =COUNTIF(逐章拆解!$K$3:$K$300,A37) -> 0 | C37: =IFERROR(B37/$B$4,0) -> 0
A38: 情感冲击 | B38: =COUNTIF(逐章拆解!$K$3:$K$300,A38) -> 0 | C38: =IFERROR(B38/$B$4,0) -> 0
A39: 信息量炸弹 | B39: =COUNTIF(逐章拆解!$K$3:$K$300,A39) -> 0 | C39: =IFERROR(B39/$B$4,0) -> 0
A40: 无 | B40: =COUNTIF(逐章拆解!$K$3:$K$300,A40) -> 0 | C40: =IFERROR(B40/$B$4,0) -> 0
A42: 伏笔统计
A43: 伏笔埋设标记数 | B43: =COUNTIF(逐章拆解!$G$3:$G$300,"?*") -> 0
A44: 伏笔回收标记数 | B44: =COUNTIF(逐章拆解!$H$3:$H$300,"?*") -> 0
A45: 伏笔回收率 | B45: =IFERROR(B44/B43,0) -> 0
...

Sheet 卖点提炼
A2: 卖点提炼工作区
A3: 建议在完成“逐章拆解”“结构总览”后填写，可直接用于投稿简介或推广文案。
A5: 一句话简介 | B5: 示例：被退婚的赘婿觉醒神豪系统，从被全城嘲讽到富可敌国，一路打脸装逼。
A6: 三句话简介 | B6: 示例：①主角遭遇羞辱性退婚事件，人设跌入谷底。②意外觉醒金手指，能力持续变强。③踏上复仇 / 逆袭之路，目标是彻底碾压曾经看轻他的所有人。
A7: 核心冲突关键词 | B7: 示例：阶层落差、扮猪吃虎、复仇、逆袭
A8: 金手指/设定亮点 | B8: 示例：系统按“怒气值”兑换能力，越被羞辱能力越强，设定与打脸爽点强绑定
A9: CP/关系看点 | B9: 示例：前未婚妻悔婚追妻火葬场
A10: 对标作品 | B10: 示例：与《XXX》节奏相似，但金手指机制更强绑定爽点
A11: 目标读者画像 | B11: 示例：喜欢强反差、快节奏打脸文的男频读者
A12: 推荐载体/平台 | B12: 示例：适合改编为短剧（黄金三集打脸感强）；原著适合起点/番茄男频频道
